A new study created in memory with name: no-name-71b4b07e-eb2f-40c1-af83-d87b05814904
Trial 0 failed with parameters: {'n_layers': 14, 'weight_decay': 1.2108392807795996e-05, 'n_units_l0': 31, 'n_units_l1': 8, 'n_units_l2': 11, 'n_units_l3': 32, 'n_units_l4': 5, 'n_units_l5': 126, 'n_units_l6': 5, 'n_units_l7': 6, 'n_units_l8': 6, 'n_units_l9': 25, 'n_units_l10': 13, 'n_units_l11': 6, 'n_units_l12': 109, 'n_units_l13': 27, 'optimizer': 'SGD', 'sgd_opt_learning_rate': 0.005278482271529383, 'sgd_opt_momentum': 0.013181494531409118} because of the following error: ValueError('`labels.shape` must equal `logits.shape` except for the last dimension. Received: labels.shape=(1,) and logits.shape=(1024, 1)').
Traceback (most recent call last):
  File "/home/newuser/.local/lib/python3.10/site-packages/optuna/study/_optimize.py", line 196, in _run_trial
    value_or_values = func(trial)
  File "/drive/sda2/home/newuser/Muse2024/muse2024/experiments/exp3/src/./network_optuna.py", line 102, in objective
    learn(model, optimizer, train_ds, "train")
  File "/drive/sda2/home/newuser/Muse2024/muse2024/experiments/exp3/src/./network_optuna.py", line 32, in learn
    tf.nn.sparse_softmax_cross_entropy_with_logits(logits=logits, labels=labels)
  File "/usr/local/lib/python3.10/dist-packages/tensorflow/python/util/traceback_utils.py", line 153, in error_handler
    raise e.with_traceback(filtered_tb) from None
  File "/usr/local/lib/python3.10/dist-packages/tensorflow/python/ops/nn_ops.py", line 4366, in sparse_softmax_cross_entropy_with_logits
    raise ValueError(
ValueError: `labels.shape` must equal `logits.shape` except for the last dimension. Received: labels.shape=(1,) and logits.shape=(1024, 1)
Trial 0 failed with value None.
